Workbook

Sheet Cover
A1: Apex Logistics - Loan Underwriting Financial Package
A2: Hypothetical global logistics enterprise with primary operations in the U.S. and Europe
A4: Field | B4: Value | C4: Notes
A5: Prepared For | B5: Business Loan Documentation Package | C5: Included in workbook tabs
A6: Company | B6: Apex Logistics | C6: Included in workbook tabs
A7: Reporting Currency | B7: USD ($000 unless noted) | C7: Included in workbook tabs
A8: Reporting Cutoff | B8: 2026-01-31 | C8: Included in workbook tabs
A9: Coverage | B9: Historical 2023A-2025A and YTD 2026 | C9: Included in workbook tabs
A10: Company Size Profile | B10: ~$100M annual revenue (2025A synthetic target) | C10: Included in workbook tabs
A11: Source Note | B11: Synthetic dataset for underwriting checklist demonstration | C11: Included in workbook tabs
A12: Reference Source 1 | B12: https://www.census.gov/econ | C12: Included in workbook tabs
A13: Reference Source 2 | B13: https://ec.europa.eu/eurostat | C13: Included in workbook tabs
A14: Reference Source 3 | B14: https://fred.stlouisfed.org | C14: Included in workbook tabs

Sheet Assumptions
A1: Model Assumptions
A2: Raw input drivers and source references
A4: Input | B4: Value | C4: Unit | D4: Description | E4: Source URL
A5: Tax Rate | B5: 0.27 | C5: % | D5: Effective blended tax rate | E5: https://fred.stlouisfed.org/series/FYFRGDA188S
A6: U.S. Revenue Share | B6: 0.62 | C6: % | D6: Share of revenue generated in the U.S. | E6: https://www.census.gov/econ
A7: Europe Revenue Share | B7: 0.38 | C7: % | D7: Share of revenue generated in Europe | E7: https://ec.europa.eu/eurostat
A8: Avg Diesel Cost Index | B8: 1 | C8: Index | D8: Indexed fuel cost assumption | E8: https://www.eia.gov/petroleum/gasdiesel/
A9: Avg DSO | B9: 48 | C9: Days | D9: Days sales outstanding assumption | E9: https://www.cfainstitute.org
A10: Avg DPO | B10: 36 | C10: Days | D10: Days payable outstanding assumption | E10: https://www.cfainstitute.org
A11: Working Capital Buffer | B11: 2050 | C11: USD ($000) | D11: Target liquidity buffer | E11: https://www.federalreserve.gov
A12: YTD End Date | B12: 46053 | C12: Date | D12: Current reporting cutoff | E12: https://www.sec.gov

Sheet P&L
A1: Profit & Loss Statement
A2: Historical and YTD performance (USD $000)
A4: Line Item | B4: 2023A | C4: 2024A | D4: 2025A | E4: 2026 YTD (Jan)
A6: Revenue
A7: Linehaul Revenue | B7: 60137 | C7: 66059 | D7: 71982 | E7: 6287
A8: Warehousing Revenue | B8: 15490 | C8: 17084 | D8: 18679 | E8: 1595
A9: Customs & Other Services | B9: 7289 | C9: 8200 | D9: 9339 | E9: 774
A10: Total Revenue | B10: =SUM(B7:B9) | C10: =SUM(C7:C9) | D10: =SUM(D7:D9) | E10: =SUM(E7:E9)
A12: Operating Costs
A13: Linehaul & Delivery Costs | B13: 34624 | C13: 37722 | D13: 41139 | E13: 3576
A14: Fuel Costs | B14: 8884 | C14: 9294 | D14: 9658 | E14: 802
A15: Labor & Benefits | B15: 11936 | C15: 12938 | D15: 14077 | E15: 1194
A16: Facility & Warehouse | B16: 4419 | C16: 4692 | D16: 4920 | E16: 419
A17: Technology & Communications | B17: 1913 | C17: 2141 | D17: 2415 | E17: 205
A18: General & Administrative | B18: 3781 | C18: 4055 | D18: 4419 | E18: 369
A19: Total Operating Costs | B19: =SUM(B13:B18) | C19: =SUM(C13:C18) | D19: =SUM(D13:D18) | E19: =SUM(E13:E18)
A20: EBITDA | B20: =B10-B19 | C20: =C10-C19 | D20: =D10-D19 | E20: =E10-E19
A22: Non-Operating and Tax
A23: Depreciation & Amortization | B23: 2096 | C23: 2232 | D23: 2415 | E23: 200
A24: Operating Income (EBIT) | B24: =B20-B23 | C24: =C20-C23 | D24: =D20-D23 | E24: =E20-E23
A25: Interest Expense | B25: 820 | C25: 1002 | D25: 1207 | E25: 100
A26: Other Income/(Expense) | B26: 114 | C26: 82 | D26: 55 | E26: 5
A27: Pre-Tax Income | B27: =B24-B25+B26 | C27: =C24-C25+C26 | D27: =D24-D25+D26 | E27: =E24-E25+E26
A28: Income Tax Expense | B28: =IF(B27>0,B27*Assumptions!$B$5,0) | C28: =IF(C27>0,C27*Assumptions!$B$5,0) | D28: =IF(D27>0,D27*Assumptions!$B$5,0) | E28: =IF(E27>0,E27*Assumptions!$B$5,0)
A29: Net Income | B29: =B27-B28 | C29: =C27-C28 | D29: =D27-D28 | E29: =E27-E28

Sheet Cash_Flow
A1: Cash Flow Statement
A2: Historical and YTD cash movement (USD $000)
A4: Line Item | B4: 2023A | C4: 2024A | D4: 2025A | E4: 2026 YTD (Jan)
A6: Operating Activities
A7: Net Income | B7: ='P&L'!B29 | C7: ='P&L'!C29 | D7: ='P&L'!D29 | E7: ='P&L'!E29
A8: Depreciation & Amortization | B8: ='P&L'!B23 | C8: ='P&L'!C23 | D8: ='P&L'!D23 | E8: ='P&L'!E23
A9: Change in Accounts Receivable | B9: -683 | C9: -866 | D9: -1048 | E9: -501
A10: Change in Inventory | B10: -137 | C10: -182 | D10: -228 | E10: -91
A11: Change in Accounts Payable | B11: 547 | C11: 683 | D11: 638 | E11: 228
A12: Other Working Capital Changes | B12: 182 | C12: 137 | D12: 91 | E12: 46
A13: Net Cash from Operating Activities | B13: =SUM(B7:B12) | C13: =SUM(C7:C12) | D13: =SUM(D7:D12) | E13: =SUM(E7:E12)
A15: Investing Activities
A16: Capital Expenditures | B16: -4191 | C16: -4692 | D16: -5421 | E16: -433
A17: Acquisitions | B17: -683 | C17: -911 | D17: -547 | E17: 0
A18: Asset Sales | B18: 273 | C18: 387 | D18: 319 | E18: 0
A19: Net Cash from Investing Activities | B19: =SUM(B16:B18) | C19: =SUM(C16:C18) | D19: =SUM(D16:D18) | E19: =SUM(E16:E18)
A21: Financing Activities
A22: Debt Proceeds | B22: 2187 | C22: 2961 | D22: 3736 | E22: 820
A23: Debt Repayments | B23: -1230 | C23: -1595 | D23: -1913 | E23: -137
A24: Lease Principal Payments | B24: -866 | C24: -1002 | D24: -1093 | E24: -91
A25: Dividends Paid | B25: -638 | C25: -774 | D25: -911 | E25: 0
A26: Net Cash from Financing Activities | B26: =SUM(B22:B25) | C26: =SUM(C22:C25) | D26: =SUM(D22:D25) | E26: =SUM(E22:E25)
A27: Net Change in Cash | B27: =B13+B19+B26 | C27: =C13+C19+C26 | D27: =D13+D19+D26 | E27: =E13+E19+E26
A28: Beginning Cash Balance | B28: 7289 | C28: =B29 | D28: =C29 | E28: =D29
A29: Ending Cash Balance | B29: =B28+B27 | C29: =C28+C27 | D29: =D28+D27 | E29: =E28+E27

Sheet Balance_Sheet
A1: Balance Sheet
A2: Historical and YTD position (USD $000)
A4: Line Item | B4: 2023A | C4: 2024A | D4: 2025A | E4: 2026 YTD (Jan)
A6: Assets
A7: Cash & Equivalents | B7: =Cash_Flow!B30 | C7: =Cash_Flow!C30 | D7: =Cash_Flow!D30 | E7: =Cash_Flow!E30
A8: Accounts Receivable | B8: 9339 | C8: 10205 | D8: 11253 | E8: 11754
A9: Inventory | B9: 1868 | C9: 2050 | D9: 2278 | E9: 2369
A10: Prepaid Expenses | B10: 820 | C10: 866 | D10: 957 | E10: 1002
A11: Total Current Assets | B11: =SUM(B7:B10) | C11: =SUM(C7:C10) | D11: =SUM(D7:D10) | E11: =SUM(E7:E10)
A12: Property, Plant & Equipment (Net) | B12: 23235 | C12: 24966 | D12: 26970 | E12: 27380
A13: Right-of-Use Assets | B13: 5103 | C13: 4784 | D13: 4465 | E13: 4374
A14: Intangible Assets | B14: 3462 | C14: 3280 | D14: 3144 | E14: 3098
A15: Other Non-Current Assets | B15: 1321 | C15: 1412 | D15: 1503 | E15: 1549
A16: Total Assets | B16: =B11+SUM(B12:B15) | C16: =C11+SUM(C12:C15) | D16: =D11+SUM(D12:D15) | E16: =E11+SUM(E12:E15)
A18: Liabilities & Equity
A19: Accounts Payable | B19: 6925 | C19: 7608 | D19: 8246 | E19: 8474
A20: Accrued Expenses | B20: 4465 | C20: 4829 | D20: 5194 | E20: 5421
A21: Current Portion of Long-Term Debt | B21: 1640 | C21: 1913 | D21: 2187 | E21: 2278
A22: Operating Lease Liabilities (Current) | B22: 957 | C22: 1002 | D22: 1048 | E22: 1048
A23: Total Current Liabilities | B23: =SUM(B19:B22) | C23: =SUM(C19:C22) | D23: =SUM(D19:D22) | E23: =SUM(E19:E22)
A24: Long-Term Debt | B24: 10387 | C24: 11481 | D24: 12711 | E24: 13257
A25: Operating Lease Liabilities (Non-Current) | B25: 3964 | C25: 3599 | D25: 3235 | E25: 3144
A26: Deferred Tax Liabilities | B26: 820 | C26: 866 | D26: 957 | E26: 1002
A27: Total Liabilities | B27: =B23+SUM(B24:B26) | C27: =C23+SUM(C24:C26) | D27: =D23+SUM(D24:D26) | E27: =E23+SUM(E24:E26)
A28: Common Stock | B28: 4100 | C28: 4100 | D28: 4100 | E28: 4100
A29: Retained Earnings (Plug) | B29: =B16-B27-B28-B30 | C29: =C16-C27-C28-C30 | D29: =D16-D27-D28-D30 | E29: =E16-E27-E28-E30
A30: Accumulated OCI | B30: -273 | C30: -205 | D30: -146 | E30: -137
A31: Total Equity | B31: =B28+B29+B30 | C31: =C28+C29+C30 | D31: =D28+D29+D30 | E31: =E28+E29+E30
A32: Total Liabilities & Equity | B32: =B27+B31 | C32: =C27+C31 | D32: =D27+D31 | E32: =E27+E31
A33: Balance Check (should be 0) | B33: =B16-B32 | C33: =C16-C32 | D33: =D16-D32 | E33: =E16-E32

Sheet Bank_Statements
A1: Business Bank Statements (Last 12 Months)
A2: Monthly statement summary across operating and payroll accounts (USD $000)
A4: Statement Month End | B4: Bank Name | C4: Account | D4: Masked Account # | E4: Beginning Balance | F4: Total Credits | G4: Total Debits | H4: Ending Balance | I4: Average Ledger Balance | J4: Source URL
A5: 45716 | B5: JPMorgan Chase | C5: U.S. Operating | D5: ****-1442 | E5: 4032 | F5: 10412 | G5: 9852 | H5: 4592 | I5: 4345 | J5: https://www.frbservices.org
A6: 45716 | B6: Deutsche Bank | C6: EU Operating | D6: ****-9921 | E6: 2925 | F6: 7888 | G6: 7742 | H6: 3071 | I6: 2954 | J6: https://www.ecb.europa.eu/paym
A7: 45716 | B7: HSBC | C7: Payroll Clearing | D7: ****-5510 | E7: 565 | F7: 2333 | G7: 1699 | H7: 1199 | I7: 943 | J7: https://www.bis.org
A8: 45747 | B8: JPMorgan Chase | C8: U.S. Operating | D8: ****-1442 | E8: 4592 | F8: 10188 | G8: 9620 | H8: 5160 | I8: 4830 | J8: https://www.frbservices.org
A9: 45747 | B9: Deutsche Bank | C9: EU Operating | D9: ****-9921 | E9: 3071 | F9: 8678 | G9: 8450 | H9: 3299 | I9: 3134 | J9: https://www.ecb.europa.eu/paym
A10: 45747 | B10: HSBC | C10: Payroll Clearing | D10: ****-5510 | E10: 1199 | F10: 2077 | G10: 1766 | H10: 1510 | I10: 1394 | J10: https://www.bis.org
A11: 45777 | B11: JPMorgan Chase | C11: U.S. Operating | D11: ****-1442 | E11: 5160 | F11: 9870 | G11: 9797 | H11: 5233 | I11: 5185 | J11: https://www.frbservices.org
A12: 45777 | B12: Deutsche Bank | C12: EU Operating | D12: ****-9921 | E12: 3299 | F12: 7916 | G12: 8406 | H12: 2809 | I12: 2998 | J12: https://www.ecb.europa.eu/paym
A13: 45777 | B13: HSBC | C13: Payroll Clearing | D13: ****-5510 | E13: 1510 | F13: 2037 | G13: 1676 | H13: 1871 | I13: 1656 | J13: https://www.bis.org
A14: 45808 | B14: JPMorgan Chase | C14: U.S. Operating | D14: ****-1442 | E14: 5233 | F14: 10342 | G14: 10402 | H14: 5173 | I14: 5171 | J14: https://www.frbservices.org
A15: 45808 | B15: Deutsche Bank | C15: EU Operating | D15: ****-9921 | E15: 2809 | F15: 8031 | G15: 8225 | H15: 2615 | I15: 2690 | J15: https://www.ecb.europa.eu/paym
A16: 45808 | B16: HSBC | C16: Payroll Clearing | D16: ****-5510 | E16: 1871 | F16: 1796 | G16: 1965 | H16: 1702 | I16: 1813 | J16: https://www.bis.org
... A40: 46053 | B40: HSBC | C40: Payroll Clearing | D40: ****-5510 | E40: 2059 | F40: 2466 | G40: 2151 | H40: 2374 | I40: 2254 | J40: https://www.bis.org

Sheet AR_Aging
A1: Accounts Receivable Aging (Current)
A2: As of 2026-01-31 (USD $000)
A4: Customer | B4: Region | C4: Invoice # | D4: Invoice Date | E4: Due Date | F4: Current | G4: 1-30 | H4: 31-60 | I4: 61-90 | J4: 90+ | K4: Total | L4: Source URL
A5: Orion Retail Group | B5: US | C5: AR-20260001 | D5: 46028 | E5: 46058 | F5: 1211 | G5: 0 | H5: 0 | I5: 0 | J5: 0 | K5: =SUM(F5:J5) | L5: https://www.apexlogistics.example/internal/ar-ledger-2026-01-31
A6: NordPort Manufacturing | B6: EU | C6: AR-20260002 | D6: 46028 | E6: 46058 | F6: 1193 | G6: 0 | H6: 0 | I6: 0 | J6: 0 | K6: =SUM(F6:J6) | L6: https://www.apexlogistics.example/internal/ar-ledger-2026-01-31
A7: Atlas Pharma | B7: US | C7: AR-20260003 | D7: 46013 | E7: 46043 | F7: 0 | G7: 951 | H7: 0 | I7: 0 | J7: 0 | K7: =SUM(F7:J7) | L7: https://www.apexlogistics.example/internal/ar-ledger-2026-01-31
A8: BlueRock Foods | B8: EU | C8: AR-20260004 | D8: 45993 | E8: 46023 | F8: 0 | G8: 0 | H8: 1229 | I8: 0 | J8: 0 | K8: =SUM(F8:J8) | L8: https://www.apexlogistics.example/internal/ar-ledger-2026-01-31
A9: Summit Auto Parts | B9: US | C9: AR-20260005 | D9: 45993 | E9: 46023 | F9: 0 | G9: 0 | H9: 449 | I9: 0 | J9: 0 | K9: =SUM(F9:J9) | L9: https://www.apexlogistics.example/internal/ar-ledger-2026-01-31
A10: Horizon Homeware | B10: EU | C10: AR-20260006 | D10: 45928 | E10: 45958 | F10: 0 | G10: 0 | H10: 0 | I10: 0 | J10: 680 | K10: =SUM(F10:J10) | L10: https://www.apexlogistics.example/internal/ar-ledger-2026-01-31
A11: Aquila Electronics | B11: US | C11: AR-20260007 | D11: 46028 | E11: 46058 | F11: 679 | G11: 0 | H11: 0 | I11: 0 | J11: 0 | K11: =SUM(F11:J11) | L11: https://www.apexlogistics.example/internal/ar-ledger-2026-01-31
A12: NorthSea Equipment | B12: EU | C12: AR-20260008 | D12: 45963 | E12: 45993 | F12: 0 | G12: 0 | H12: 0 | I12: 816 | J12: 0 | K12: =SUM(F12:J12) | L12: https://www.apexlogistics.example/internal/ar-ledger-2026-01-31
A13: Delta Medical | B13: US | C13: AR-20260009 | D13: 45993 | E13: 46023 | F13: 0 | G13: 0 | H13: 366 | I13: 0 | J13: 0 | K13: =SUM(F13:J13) | L13: https://www.apexlogistics.example/internal/ar-ledger-2026-01-31
A14: Titan Consumer | B14: EU | C14: AR-20260010 | D14: 45993 | E14: 46023 | F14: 0 | G14: 0 | H14: 783 | I14: 0 | J14: 0 | K14: =SUM(F14:J14) | L14: https://www.apexlogistics.example/internal/ar-ledger-2026-01-31
A15: Pioneer Industrial | B15: US | C15: AR-20260011 | D15: 46028 | E15: 46058 | F15: 558 | G15: 0 | H15: 0 | I15: 0 | J15: 0 | K15: =SUM(F15:J15) | L15: https://www.apexlogistics.example/internal/ar-ledger-2026-01-31
A16: Vega Textiles | B16: EU | C16: AR-20260012 | D16: 46028 | E16: 46058 | F16: 560 | G16: 0 | H16: 0 | I16: 0 | J16: 0 | K16: =SUM(F16:J16) | L16: https://www.apexlogistics.example/internal/ar-ledger-2026-01-31
... A19: Peak Beverages | B19: US | C19: AR-20260015 | D19: 46028 | E19: 46058 | F19: 347 | G19: 0 | H19: 0 | I19: 0 | J19: 0 | K19: =SUM(F19:J19) | L19: https://www.apexlogistics.example/internal/ar-ledger-2026-01-31
A20: Total A/R | F20: =SUM(F5:F19) | G20: =SUM(G5:G19) | H20: =SUM(H5:H19) | I20: =SUM(I5:I19) | J20: =SUM(J5:J19) | K20: =SUM(K5:K19)

Sheet AP_Aging
A1: Accounts Payable Aging (Current)
A2: As of 2026-01-31 (USD $000)
A4: Vendor | B4: Region | C4: Invoice # | D4: Invoice Date | E4: Due Date | F4: Current | G4: 1-30 | H4: 31-60 | I4: 61-90 | J4: 90+ | K4: Total | L4: Source URL
A5: SwiftFuel Energy | B5: US | C5: AP-20260001 | D5: 45938 | E5: 45968 | F5: 0 | G5: 0 | H5: 0 | I5: 0 | J5: 173 | K5: =SUM(F5:J5) | L5: https://www.apexlogistics.example/internal/ap-ledger-2026-01-31
A6: EuroFleet Leasing | B6: EU | C6: AP-20260002 | D6: 45999 | E6: 46029 | F6: 0 | G6: 0 | H6: 708 | I6: 0 | J6: 0 | K6: =SUM(F6:J6) | L6: https://www.apexlogistics.example/internal/ap-ledger-2026-01-31
A7: Harbor Rail Systems | B7: US | C7: AP-20260003 | D7: 45938 | E7: 45968 | F7: 0 | G7: 0 | H7: 0 | I7: 0 | J7: 391 | K7: =SUM(F7:J7) | L7: https://www.apexlogistics.example/internal/ap-ledger-2026-01-31
A8: Mercury Packaging | B8: EU | C8: AP-20260004 | D8: 46035 | E8: 46065 | F8: 618 | G8: 0 | H8: 0 | I8: 0 | J8: 0 | K8: =SUM(F8:J8) | L8: https://www.apexlogistics.example/internal/ap-ledger-2026-01-31
A9: Peak Staffing | B9: US | C9: AP-20260005 | D9: 45999 | E9: 46029 | F9: 0 | G9: 0 | H9: 498 | I9: 0 | J9: 0 | K9: =SUM(F9:J9) | L9: https://www.apexlogistics.example/internal/ap-ledger-2026-01-31
A10: Danube Logistics Parks | B10: EU | C10: AP-20260006 | D10: 45971 | E10: 46001 | F10: 0 | G10: 0 | H10: 0 | I10: 115 | J10: 0 | K10: =SUM(F10:J10) | L10: https://www.apexlogistics.example/internal/ap-ledger-2026-01-31
A11: TriState Tires | B11: US | C11: AP-20260007 | D11: 46035 | E11: 46065 | F11: 202 | G11: 0 | H11: 0 | I11: 0 | J11: 0 | K11: =SUM(F11:J11) | L11: https://www.apexlogistics.example/internal/ap-ledger-2026-01-31
A12: Rhein Tech Systems | B12: EU | C12: AP-20260008 | D12: 45971 | E12: 46001 | F12: 0 | G12: 0 | H12: 0 | I12: 763 | J12: 0 | K12: =SUM(F12:J12) | L12: https://www.apexlogistics.example/internal/ap-ledger-2026-01-31
A13: Atlas Insurance | B13: US | C13: AP-20260009 | D13: 46021 | E13: 46051 | F13: 0 | G13: 453 | H13: 0 | I13: 0 | J13: 0 | K13: =SUM(F13:J13) | L13: https://www.apexlogistics.example/internal/ap-ledger-2026-01-31
A14: Nordic Warehousing | B14: EU | C14: AP-20260010 | D14: 46035 | E14: 46065 | F14: 605 | G14: 0 | H14: 0 | I14: 0 | J14: 0 | K14: =SUM(F14:J14) | L14: https://www.apexlogistics.example/internal/ap-ledger-2026-01-31
A15: Metro Utilities | B15: US | C15: AP-20260011 | D15: 45999 | E15: 46029 | F15: 0 | G15: 0 | H15: 718 | I15: 0 | J15: 0 | K15: =SUM(F15:J15) | L15: https://www.apexlogistics.example/internal/ap-ledger-2026-01-31
A16: Baltic Freight Services | B16: EU | C16: AP-20260012 | D16: 45938 | E16: 45968 | F16: 0 | G16: 0 | H16: 0 | I16: 0 | J16: 525 | K16: =SUM(F16:J16) | L16: https://www.apexlogistics.example/internal/ap-ledger-2026-01-31
... A19: BlueRoute Maintenance | B19: US | C19: AP-20260015 | D19: 45971 | E19: 46001 | F19: 0 | G19: 0 | H19: 0 | I19: 513 | J19: 0 | K19: =SUM(F19:J19) | L19: https://www.apexlogistics.example/internal/ap-ledger-2026-01-31
A20: Total A/P | F20: =SUM(F5:F19) | G20: =SUM(G5:G19) | H20: =SUM(H5:H19) | I20: =SUM(I5:I19) | J20: =SUM(J5:J19) | K20: =SUM(K5:K19)

Sheet Debt_Schedule
A1: Debt Schedule
A2: Outstanding obligations, maturities, and pricing (USD $000)
A4: Facility | B4: Lender | C4: Currency | D4: Original Amount | E4: Outstanding Principal | F4: Rate Type | G4: All-in Rate | H4: Spread | I4: Maturity Date | J4: Amortization | K4: Estimated Monthly Payment | L4: Net Leverage Covenant | M4: Security | N4: Source URL
A5: Term Loan A | B5: JPMorgan Chase | C5: USD | D5: 10023 | E5: 7882 | F5: Floating | G5: 0.064 | H5: 0.021 | I5: 46934 | J5: 60-month straight-line | K5: =IFERROR(-PMT(G5/12,MAX(1,ROUND((I5-DATE(2026,1,31))/30,0)),E5),0) | L5: 4.5 | M5: Senior secured | N5: https://www.sec.gov
A6: Term Loan B | B6: BNP Paribas | C6: EUR | D6: 6834 | E6: 5376 | F6: Fixed | G6: 0.0515 | H6: 0 | I6: 47208 | J6: 72-month amortizing | K6: =IFERROR(-PMT(G6/12,MAX(1,ROUND((I6-DATE(2026,1,31))/30,0)),E6),0) | L6: 4.25 | M6: Senior secured | N6: https://www.esma.europa.eu
A7: Revolving Credit | B7: Bank of America | C7: USD | D7: 8200 | E7: 4191 | F7: Floating | G7: 0.0675 | H7: 0.024 | I7: 46752 | J7: Bullet at maturity | K7: =IFERROR(-PMT(G7/12,MAX(1,ROUND((I7-DATE(2026,1,31))/30,0)),E7),0) | L7: 4.75 | M7: Senior secured | N7: https://www.ffiec.gov
A8: Equipment Lease | B8: Deutsche Leasing | C8: EUR | D8: 2460 | E8: 1412 | F8: Fixed | G8: 0.048 | H8: 0 | I8: 47026 | J8: 48-month amortizing | K8: =IFERROR(-PMT(G8/12,MAX(1,ROUND((I8-DATE(2026,1,31))/30,0)),E8),0) | L8: 4.25 | M8: Secured by equipment | N8: https://www.ecb.europa.eu
A9: Warehouse Lease Liability | B9: CBRE Finance | C9: USD | D9: 3918 | E9: 2916 | F9: Fixed | G9: 0.046 | H9: 0 | I9: 47879 | J9: IFRS 16/ASC 842 schedule | K9: =IFERROR(-PMT(G9/12,MAX(1,ROUND((I9-DATE(2026,1,31))/30,0)),E9),0) | L9: 4 | M9: Leasehold | N9: https://www.ifrs.org
A10: Fleet Financing | B10: Wells Fargo | C10: USD | D10: 3280 | E10: 1959 | F10: Floating | G10: 0.0625 | H10: 0.0195 | I10: 47087 | J10: 54-month amortizing | K10: =IFERROR(-PMT(G10/12,MAX(1,ROUND((I10-DATE(2026,1,31))/30,0)),E10),0) | L10: 4.25 | M10: Secured by vehicles | N10: https://www.federalreserve.gov
A11: Total Debt / Lease Exposure | D11: =SUM(D5:D10) | E11: =SUM(E5:E10) | K11: =SUM(K5:K10)
A12: Weighted Average Interest Rate | G12: =SUMPRODUCT(E5:E10,G5:G10)/SUM(E5:E10)
A14: Debt Service Coverage Ratio (DSCR) - Case A (Expected Below 1.0x)
A15: Annualized EBITDA (Base) | K15: ='P&L'!E20*12
A16: Stress Haircut Applied to EBITDA | B16: 0.2
A17: Annualized EBITDA (Stressed) | K17: =K15*B16
A18: Annual Debt Service | K18: =K11*12
A19: DSCR (Stressed EBITDA / Debt Service) | K19: =IFERROR(K17/K18,0)
A20: DSCR Target Threshold | K20: 1
A21: Target Test Result | K21: =IF(K19>=K20,"PASS","FAIL")

Sheet Trial_Balance
A1: Trial Balance
A2: As of 2026-01-31 (USD $000)
A4: Account # | B4: Account Name | C4: Debit | D4: Credit | E4: Net Balance | F4: Type
A5: 1000 | B5: Cash & Equivalents | C5: 35660 | D5: 0 | E5: =C5-D5 | F5: Asset
A6: 1100 | B6: Accounts Receivable | C6: 11754 | D6: 0 | E6: =C6-D6 | F6: Asset
A7: 1200 | B7: Inventory | C7: 2369 | D7: 0 | E7: =C7-D7 | F7: Asset
A8: 1300 | B8: Prepaid Expenses | C8: 1002 | D8: 0 | E8: =C8-D8 | F8: Asset
A9: 1500 | B9: Property, Plant & Equipment (Net) | C9: 27380 | D9: 0 | E9: =C9-D9 | F9: Asset
A10: 1510 | B10: Right-of-Use Assets | C10: 4374 | D10: 0 | E10: =C10-D10 | F10: Asset
A11: 1600 | B11: Intangible Assets | C11: 3098 | D11: 0 | E11: =C11-D11 | F11: Asset
A12: 1700 | B12: Other Non-Current Assets | C12: 1549 | D12: 0 | E12: =C12-D12 | F12: Asset
A13: 2000 | B13: Accounts Payable | C13: 0 | D13: 8474 | E13: =C13-D13 | F13: Liability
A14: 2100 | B14: Accrued Expenses | C14: 0 | D14: 5421 | E14: =C14-D14 | F14: Liability
A15: 2200 | B15: Current Portion LT Debt | C15: 0 | D15: 2278 | E15: =C15-D15 | F15: Liability
A16: 2210 | B16: Current Lease Liabilities | C16: 0 | D16: 1048 | E16: =C16-D16 | F16: Liability
... A35: 5400 | B35: Income Tax Expense | C35: 485 | D35: 0 | E35: =C35-D35 | F35: Expense
B36: Total | C36: =SUM(C5:C35) | D36: =SUM(D5:D35) | E36: =C36-D36
B37: Balance Check (should be 0) | E37: =C36-D36

Sheet GL_Detail
A1: General Ledger Detail
A2: YTD journal detail through 2026-01-31 (USD $000)
A4: Journal Date | B4: Journal ID | C4: Account # | D4: Account Name | E4: Entity | F4: Department | G4: Description | H4: Debit | I4: Credit | J4: Running Balance | K4: Source URL
A5: 46024 | B5: J260001 | C5: 1100 | D5: Accounts Receivable | E5: US | F5: Linehaul | G5: Weekly freight billing | H5: 843 | I5: 0 | J5: =IF(ROW()=5,H5-I5,J4+H5-I5) | K5: https://www.apexlogistics.example/internal/gl-detail-2026-ytd
A6: 46024 | B6: J260001 | C6: 4000 | D6: Linehaul Revenue | E6: US | F6: Linehaul | G6: Weekly freight billing | H6: 0 | I6: 843 | J6: =IF(ROW()=5,H5-I5,J5+H6-I6) | K6: https://www.apexlogistics.example/internal/gl-detail-2026-ytd
A7: 46025 | B7: J260002 | C7: 1000 | D7: Cash & Equivalents | E7: US | F7: Treasury | G7: Customer remittance lockbox | H7: 738 | I7: 0 | J7: =IF(ROW()=5,H5-I5,J6+H7-I7) | K7: https://www.apexlogistics.example/internal/gl-detail-2026-ytd
A8: 46025 | B8: J260002 | C8: 1100 | D8: Accounts Receivable | E8: US | F8: Linehaul | G8: Customer remittance lockbox | H8: 0 | I8: 738 | J8: =IF(ROW()=5,H5-I5,J7+H8-I8) | K8: https://www.apexlogistics.example/internal/gl-detail-2026-ytd
A9: 46026 | B9: J260003 | C9: 5010 | D9: Fuel Costs | E9: US | F9: Linehaul | G9: Fuel card settlement | H9: 141 | I9: 0 | J9: =IF(ROW()=5,H5-I5,J8+H9-I9) | K9: https://www.apexlogistics.example/internal/gl-detail-2026-ytd
A10: 46026 | B10: J260003 | C10: 2000 | D10: Accounts Payable | E10: US | F10: Linehaul | G10: Fuel card settlement | H10: 0 | I10: 141 | J10: =IF(ROW()=5,H5-I5,J9+H10-I10) | K10: https://www.apexlogistics.example/internal/gl-detail-2026-ytd
A11: 46027 | B11: J260004 | C11: 5020 | D11: Labor & Benefits | E11: US | F11: Operations | G11: Biweekly payroll accrual | H11: 219 | I11: 0 | J11: =IF(ROW()=5,H5-I5,J10+H11-I11) | K11: https://www.apexlogistics.example/internal/gl-detail-2026-ytd
A12: 46027 | B12: J260004 | C12: 2100 | D12: Accrued Expenses | E12: US | F12: Operations | G12: Biweekly payroll accrual | H12: 0 | I12: 219 | J12: =IF(ROW()=5,H5-I5,J11+H12-I12) | K12: https://www.apexlogistics.example/internal/gl-detail-2026-ytd
A13: 46028 | B13: J260005 | C13: 1100 | D13: Accounts Receivable | E13: EU | F13: Warehousing | G13: Storage and handling billing | H13: 419 | I13: 0 | J13: =IF(ROW()=5,H5-I5,J12+H13-I13) | K13: https://www.apexlogistics.example/internal/gl-detail-2026-ytd
A14: 46028 | B14: J260005 | C14: 4010 | D14: Warehousing Revenue | E14: EU | F14: Warehousing | G14: Storage and handling billing | H14: 0 | I14: 419 | J14: =IF(ROW()=5,H5-I5,J13+H14-I14) | K14: https://www.apexlogistics.example/internal/gl-detail-2026-ytd
A15: 46029 | B15: J260006 | C15: 5030 | D15: Facility & Warehouse | E15: EU | F15: Warehousing | G15: Warehouse rent accrual | H15: 77 | I15: 0 | J15: =IF(ROW()=5,H5-I5,J14+H15-I15) | K15: https://www.apexlogistics.example/internal/gl-detail-2026-ytd
A16: 46029 | B16: J260006 | C16: 2000 | D16: Accounts Payable | E16: EU | F16: Warehousing | G16: Warehouse rent accrual | H16: 0 | I16: 77 | J16: =IF(ROW()=5,H5-I5,J15+H16-I16) | K16: https://www.apexlogistics.example/internal/gl-detail-2026-ytd
A17: 46030 | B17: J260007 | C17: 5100 | D17: Depreciation & Amortization | E17: US | F17: Accounting | G17: Monthly depreciation | H17: 200 | I17: 0 | J17: =IF(ROW()=5,H5-I5,J16+H17-I17) | K17: https://www.apexlogistics.example/internal/gl-detail-2026-ytd
A18: 46030 | B18: J260007 | C18: 1500 | D18: Property, Plant & Equipment (Net) | E18: US | F18: Accounting | G18: Monthly depreciation | H18: 0 | I18: 200 | J18: =IF(ROW()=5,H5-I5,J17+H18-I18) | K18: https://www.apexlogistics.example/internal/gl-detail-2026-ytd
A19: 46031 | B19: J260008 | C19: 5200 | D19: Interest Expense | E19: US | F19: Treasury | G19: Debt interest accrual | H19: 100 | I19: 0 | J19: =IF(ROW()=5,H5-I5,J18+H19-I19) | K19: https://www.apexlogistics.example/internal/gl-detail-2026-ytd
A20: 46031 | B20: J260008 | C20: 1000 | D20: Cash & Equivalents | E20: US | F20: Treasury | G20: Debt interest accrual | H20: 0 | I20: 100 | J20: =IF(ROW()=5,H5-I5,J19+H20-I20) | K20: https://www.apexlogistics.example/internal/gl-detail-2026-ytd
A21: 46032 | B21: J260009 | C21: 1000 | D21: Cash & Equivalents | E21: US | F21: Treasury | G21: Revolver draw | H21: 820 | I21: 0 | J21: =IF(ROW()=5,H5-I5,J20+H21-I21) | K21: https://www.apexlogistics.example/internal/gl-detail-2026-ytd
A22: 46032 | B22: J260009 | C22: 2200 | D22: Current Portion LT Debt | E22: US | F22: Treasury | G22: Revolver draw | H22: 0 | I22: 820 | J22: =IF(ROW()=5,H5-I5,J21+H22-I22) | K22: https://www.apexlogistics.example/internal/gl-detail-2026-ytd
A23: 46033 | B23: J260010 | C23: 5400 | D23: Income Tax Expense | E23: US | F23: Tax | G23: Current tax provision | H23: 485 | I23: 0 | J23: =IF(ROW()=5,H5-I5,J22+H23-I23) | K23: https://www.apexlogistics.example/internal/gl-detail-2026-ytd
A24: 46033 | B24: J260010 | C24: 2400 | D24: Deferred Tax Liabilities | E24: US | F24: Tax | G24: Current tax provision | H24: 0 | I24: 485 | J24: =IF(ROW()=5,H5-I5,J23+H24-I24) | K24: https://www.apexlogistics.example/internal/gl-detail-2026-ytd
A25: 46034 | B25: J260011 | C25: 4020 | D25: Customs & Other Revenue | E25: EU | F25: Customs | G25: Brokerage revenue reclass | H25: 0 | I25: 77 | J25: =IF(ROW()=5,H5-I5,J24+H25-I25) | K25: https://www.apexlogistics.example/internal/gl-detail-2026-ytd
A26: 46034 | B26: J260011 | C26: 1100 | D26: Accounts Receivable | E26: EU | F26: Customs | G26: Brokerage revenue reclass | H26: 77 | I26: 0 | J26: =IF(ROW()=5,H5-I5,J25+H26-I26) | K26: https://www.apexlogistics.example/internal/gl-detail-2026-ytd
A27: 46035 | B27: J260012 | C27: 2000 | D27: Accounts Payable | E27: US | F27: AP | G27: Vendor payment run | H27: 241 | I27: 0 | J27: =IF(ROW()=5,H5-I5,J26+H27-I27) | K27: https://www.apexlogistics.example/internal/gl-detail-2026-ytd
A28: 46035 | B28: J260012 | C28: 1000 | D28: Cash & Equivalents | E28: US | F28: Treasury | G28: Vendor payment run | H28: 0 | I28: 241 | J28: =IF(ROW()=5,H5-I5,J27+H28-I28) | K28: https://www.apexlogistics.example/internal/gl-detail-2026-ytd
A29: 46036 | B29: J260013 | C29: 2100 | D29: Accrued Expenses | E29: US | F29: Payroll | G29: Payroll settlement | H29: 205 | I29: 0 | J29: =IF(ROW()=5,H5-I5,J28+H29-I29) | K29: https://www.apexlogistics.example/internal/gl-detail-2026-ytd
A30: 46036 | B30: J260013 | C30: 1000 | D30: Cash & Equivalents | E30: US | F30: Payroll | G30: Payroll settlement | H30: 0 | I30: 205 | J30: =IF(ROW()=5,H5-I5,J29+H30-I30) | K30: https://www.apexlogistics.example/internal/gl-detail-2026-ytd
A31: 46037 | B31: J260014 | C31: 5040 | D31: Technology & Communications | E31: US | F31: IT | G31: TMS software license | H31: 43 | I31: 0 | J31: =IF(ROW()=5,H5-I5,J30+H31-I31) | K31: https://www.apexlogistics.example/internal/gl-detail-2026-ytd
A32: 46037 | B32: J260014 | C32: 2000 | D32: Accounts Payable | E32: US | F32: IT | G32: TMS software license | H32: 0 | I32: 43 | J32: =IF(ROW()=5,H5-I5,J31+H32-I32) | K32: https://www.apexlogistics.example/internal/gl-detail-2026-ytd
A33: 46038 | B33: J260015 | C33: 5050 | D33: General & Administrative | E33: US | F33: Corporate | G33: Professional services | H33: 59 | I33: 0 | J33: =IF(ROW()=5,H5-I5,J32+H33-I33) | K33: https://www.apexlogistics.example/internal/gl-detail-2026-ytd
A34: 46038 | B34: J260015 | C34: 2000 | D34: Accounts Payable | E34: US | F34: Corporate | G34: Professional services | H34: 0 | I34: 59 | J34: =IF(ROW()=5,H5-I5,J33+H34-I34) | K34: https://www.apexlogistics.example/internal/gl-detail-2026-ytd
A35: 46039 | B35: J260016 | C35: 1000 | D35: Cash & Equivalents | E35: EU | F35: Treasury | G35: Customer wire receipts | H35: 337 | I35: 0 | J35: =IF(ROW()=5,H5-I5,J34+H35-I35) | K35: https://www.apexlogistics.example/internal/gl-detail-2026-ytd
A36: 46039 | B36: J260016 | C36: 1100 | D36: Accounts Receivable | E36: EU | F36: Collections | G36: Customer wire receipts | H36: 0 | I36: 337 | J36: =IF(ROW()=5,H5-I5,J35+H36-I36) | K36: https://www.apexlogistics.example/internal/gl-detail-2026-ytd
A37: 46040 | B37: J260017 | C37: 5010 | D37: Fuel Costs | E37: EU | F37: Linehaul | G37: Diesel surcharge true-up | H37: 55 | I37: 0 | J37: =IF(ROW()=5,H5-I5,J36+H37-I37) | K37: https://www.apexlogistics.example/internal/gl-detail-2026-ytd
A38: 46040 | B38: J260017 | C38: 2000 | D38: Accounts Payable | E38: EU | F38: Linehaul | G38: Diesel surcharge true-up | H38: 0 | I38: 55 | J38: =IF(ROW()=5,H5-I5,J37+H38-I38) | K38: https://www.apexlogistics.example/internal/gl-detail-2026-ytd
A39: 46041 | B39: J260018 | C39: 2300 | D39: Long-Term Debt | E39: US | F39: Treasury | G39: Scheduled principal payment | H39: 137 | I39: 0 | J39: =IF(ROW()=5,H5-I5,J38+H39-I39) | K39: https://www.apexlogistics.example/internal/gl-detail-2026-ytd
A40: 46041 | B40: J260018 | C40: 1000 | D40: Cash & Equivalents | E40: US | F40: Treasury | G40: Scheduled principal payment | H40: 0 | I40: 137 | J40: =IF(ROW()=5,H5-I5,J39+H40-I40) | K40: https://www.apexlogistics.example/internal/gl-detail-2026-ytd
A41: 46042 | B41: J260019 | C41: 2210 | D41: Current Lease Liabilities | E41: EU | F41: Fleet | G41: Truck lease payment | H41: 91 | I41: 0 | J41: =IF(ROW()=5,H5-I5,J40+H41-I41) | K41: https://www.apexlogistics.example/internal/gl-detail-2026-ytd
...

Sheet Revenue_Concentration
A1: Revenue Concentration Report
A2: Top customers and % of sales (USD $000)
A4: Customer | B4: Region | C4: Primary Service | D4: 2025 Sales | E4: % of 2025 Sales | F4: 2026 YTD Sales | G4: % of 2026 YTD | H4: DSO (Days) | I4: Credit Terms | J4: Source URL
A5: Orion Retail Group | B5: US | C5: Linehaul | D5: 10200 | E5: =D5/'P&L'!D10 | F5: 930 | G5: =F5/'P&L'!E10 | H5: 47 | I5: Net 45 | J5: https://www.apexlogistics.example/internal/customer-revenue
A6: NordPort Manufacturing | B6: EU | C6: Linehaul | D6: 8400 | E6: =D6/'P&L'!D10 | F6: 740 | G6: =F6/'P&L'!E10 | H6: 52 | I6: Net 60 | J6: https://www.apexlogistics.example/internal/customer-revenue
A7: Atlas Pharma | B7: US | C7: Temperature-Controlled | D7: 7900 | E7: =D7/'P&L'!D10 | F7: 700 | G7: =F7/'P&L'!E10 | H7: 43 | I7: Net 45 | J7: https://www.apexlogistics.example/internal/customer-revenue
A8: BlueRock Foods | B8: EU | C8: Warehousing | D8: 6300 | E8: =D8/'P&L'!D10 | F8: 540 | G8: =F8/'P&L'!E10 | H8: 41 | I8: Net 30 | J8: https://www.apexlogistics.example/internal/customer-revenue
A9: Summit Auto Parts | B9: US | C9: Linehaul | D9: 6100 | E9: =D9/'P&L'!D10 | F9: 560 | G9: =F9/'P&L'!E10 | H9: 39 | I9: Net 30 | J9: https://www.apexlogistics.example/internal/customer-revenue
A10: Horizon Homeware | B10: EU | C10: Warehousing | D10: 5500 | E10: =D10/'P&L'!D10 | F10: 470 | G10: =F10/'P&L'!E10 | H10: 45 | I10: Net 45 | J10: https://www.apexlogistics.example/internal/customer-revenue
A11: Aquila Electronics | B11: US | C11: Customs Brokerage | D11: 4900 | E11: =D11/'P&L'!D10 | F11: 420 | G11: =F11/'P&L'!E10 | H11: 50 | I11: Net 45 | J11: https://www.apexlogistics.example/internal/customer-revenue
A12: NorthSea Equipment | B12: EU | C12: Linehaul | D12: 4700 | E12: =D12/'P&L'!D10 | F12: 400 | G12: =F12/'P&L'!E10 | H12: 54 | I12: Net 60 | J12: https://www.apexlogistics.example/internal/customer-revenue
A13: Delta Medical | B13: US | C13: Warehousing | D13: 4300 | E13: =D13/'P&L'!D10 | F13: 390 | G13: =F13/'P&L'!E10 | H13: 40 | I13: Net 30 | J13: https://www.apexlogistics.example/internal/customer-revenue
A14: Titan Consumer | B14: EU | C14: Customs Brokerage | D14: 3900 | E14: =D14/'P&L'!D10 | F14: 340 | G14: =F14/'P&L'!E10 | H14: 49 | I14: Net 45 | J14: https://www.apexlogistics.example/internal/customer-revenue
A15: Top-10 Total | D15: =SUM(D5:D14) | E15: =D15/'P&L'!D10 | F15: =SUM(F5:F14) | G15: =F15/'P&L'!E10
A17: Top-10 concentration is a key underwriting KPI.
A18: Formulas link to total revenue in 'P&L' for consistency.

Sheet Gross_Margin_Trend
A1: Gross Margin Trend by Service Line
A2: Historical and YTD margin profile (USD $000)
A4: Line Item | B4: 2023A | C4: 2024A | D4: 2025A | E4: 2026 YTD | F4: Notes
A6: Revenue
A7: Linehaul Revenue | B7: ='P&L'!B7 | C7: ='P&L'!C7 | D7: ='P&L'!D7 | E7: ='P&L'!E7 | F7: Linked from P&L
A8: Warehousing Revenue | B8: ='P&L'!B8 | C8: ='P&L'!C8 | D8: ='P&L'!D8 | E8: ='P&L'!E8 | F8: Linked from P&L
A9: Customs & Other Revenue | B9: ='P&L'!B9 | C9: ='P&L'!C9 | D9: ='P&L'!D9 | E9: ='P&L'!E9 | F9: Linked from P&L
A10: Total Revenue | B10: =SUM(B7:B9) | C10: =SUM(C7:C9) | D10: =SUM(D7:D9) | E10: =SUM(E7:E9) | F10: Cross-check to P&L totals
A12: Gross Margin Assumptions
A13: Linehaul GM % | B13: 0.185 | C13: 0.192 | D13: 0.198 | E13: 0.194 | F13: Input
A14: Warehousing GM % | B14: 0.322 | C14: 0.33 | D14: 0.338 | E14: 0.334 | F14: Input
A15: Customs GM % | B15: 0.575 | C15: 0.568 | D15: 0.56 | E15: 0.566 | F15: Input
A17: Derived Gross Profit
A18: Linehaul COGS | B18: =B7*(1-B13) | C18: =C7*(1-C13) | D18: =D7*(1-D13) | E18: =E7*(1-E13) | F18: Derived
A19: Warehousing COGS | B19: =B8*(1-B14) | C19: =C8*(1-C14) | D19: =D8*(1-D14) | E19: =E8*(1-E14) | F19: Derived
A20: Customs COGS | B20: =B9*(1-B15) | C20: =C9*(1-C15) | D20: =D9*(1-D15) | E20: =E9*(1-E15) | F20: Derived
A21: Total Service COGS | B21: =SUM(B18:B20) | C21: =SUM(C18:C20) | D21: =SUM(D18:D20) | E21: =SUM(E18:E20) | F21: Derived
A22: Gross Profit | B22: =B10-B21 | C22: =C10-C21 | D22: =D10-D21 | E22: =E10-E21 | F22: Derived
A23: Gross Margin % | B23: =IFERROR(B22/B10,0) | C23: =IFERROR(C22/C10,0) | D23: =IFERROR(D22/D10,0) | E23: =IFERROR(E22/E10,0) | F23: Derived

Sheet Inventory_Turnover
A1: Inventory Report & Turnover Metrics
A2: Inventory-based support schedules (USD $000)
A4: Current Inventory Position (As of 2026-01-31)
A5: Category | B5: Units | C5: Unit Cost | D5: Book Value | E5: Aging Bucket | F5: Eligible % | G5: Eligible Value | H5: Source URL
A6: Packaging & Pallets | B6: 8800 | C6: 0.11 | D6: 968 | E6: Current | F6: 0.95 | G6: =D6*F6 | H6: https://www.apexlogistics.example/internal/inventory-ledger
A7: Cross-Dock Spare Parts | B7: 3200 | C7: 0.18 | D7: 576 | E7: 1-90 Days | F7: 0.9 | G7: =D7*F7 | H7: https://www.apexlogistics.example/internal/inventory-ledger
A8: Fleet Maintenance Parts | B8: 2400 | C8: 0.22 | D8: 528 | E8: 1-90 Days | F8: 0.85 | G8: =D8*F8 | H8: https://www.apexlogistics.example/internal/inventory-ledger
A9: Safety & Consumables | B9: 4300 | C9: 0.07 | D9: 301 | E9: Current | F9: 0.95 | G9: =D9*F9 | H9: https://www.apexlogistics.example/internal/inventory-ledger
A10: Returns Processing Stock | B10: 1700 | C10: 0.19 | D10: 323 | E10: 90+ Days | F10: 0.5 | G10: =D10*F10 | H10: https://www.apexlogistics.example/internal/inventory-ledger
A11: Total Current Inventory | D11: =SUM(D6:D10) | G11: =SUM(G6:G10)
A13: Turnover Metrics by Period
A14: Metric | B14: 2023A | C14: 2024A | D14: 2025A | E14: 2026 YTD | F14: Annualized 2026E | G14: Notes | H14: Source URL
A15: Beginning Inventory | B15: 1750 | C15: ='Balance_Sheet'!B9 | D15: ='Balance_Sheet'!C9 | E15: ='Balance_Sheet'!D9 | F15: ='Balance_Sheet'!D9 | G15: Prior period end | H15: https://www.apexlogistics.example/internal/inventory-ledger
A16: Ending Inventory | B16: ='Balance_Sheet'!B9 | C16: ='Balance_Sheet'!C9 | D16: ='Balance_Sheet'!D9 | E16: ='Balance_Sheet'!E9 | F16: ='Balance_Sheet'!E9 | G16: Balance sheet tie | H16: https://www.apexlogistics.example/internal/inventory-ledger
A17: Average Inventory | B17: =(B15+B16)/2 | C17: =(C15+C16)/2 | D17: =(D15+D16)/2 | E17: =(E15+E16)/2 | F17: =(F15+F16)/2 | G17: Derived | H17: https://www.apexlogistics.example/internal/inventory-ledger
A18: Inventory-Linked COGS | B18: 1225 | C18: 1320 | D18: 1435 | E18: 128 | F18: =E18*12 | G18: Input / annualized | H18: https://www.cscmp.org
A19: Inventory Turnover (x) | B19: =IFERROR(B18/B17,0) | C19: =IFERROR(C18/C17,0) | D19: =IFERROR(D18/D17,0) | E19: =IFERROR(E18/E17,0) | F19: =IFERROR(F18/F17,0) | G19: COGS / Avg Inventory | H19: https://www.cscmp.org
A20: Days Inventory on Hand (DIO) | B20: =IFERROR(365/B19,0) | C20: =IFERROR(365/C19,0) | D20: =IFERROR(365/D19,0) | E20: =IFERROR(365/E19,0) | F20: =IFERROR(365/F19,0) | G20: 365 / Turnover | H20: https://www.cscmp.org

Sheet Capex_History_Plan
A1: Capital Expenditure History and Plan
A2: Historical and forward capex profile (USD $000)
A4: Category | B4: 2023A | C4: 2024A | D4: 2025A | E4: 2026P | F4: 2027P | G4: 2Y Plan Total | H4: Source URL
A5: Fleet Replacement | B5: 1700 | C5: 1870 | D5: 2125 | E5: 2350 | F5: 2450 | G5: =SUM(E5:F5) | H5: https://www.apexlogistics.example/internal/capex-plan
A6: Warehouse Automation | B6: 740 | C6: 865 | D6: 980 | E6: 1150 | F6: 1320 | G6: =SUM(E6:F6) | H6: https://www.apexlogistics.example/internal/capex-plan
A7: TMS / Data Platforms | B7: 615 | C7: 730 | D7: 850 | E7: 980 | F7: 1120 | G7: =SUM(E7:F7) | H7: https://www.apexlogistics.example/internal/capex-plan
A8: Facility Upgrades | B8: 705 | C8: 810 | D8: 960 | E8: 1090 | F8: 1240 | G8: =SUM(E8:F8) | H8: https://www.apexlogistics.example/internal/capex-plan
A9: Sustainability (EV + Energy) | B9: 431 | C9: 420 | D9: 505 | E9: 670 | F9: 850 | G9: =SUM(E9:F9) | H9: https://www.apexlogistics.example/internal/capex-plan
A10: Total Capex | B10: =SUM(B5:B9) | C10: =SUM(C5:C9) | D10: =SUM(D5:D9) | E10: =SUM(E5:E9) | F10: =SUM(F5:F9) | G10: =SUM(G5:G9)
A12: Capex Intensity Metrics
A13: Capex / Revenue | B13: =IFERROR(B10/'P&L'!B10,0) | C13: =IFERROR(C10/'P&L'!C10,0) | D13: =IFERROR(D10/'P&L'!D10,0) | E13: =IFERROR(E10/(Projections_24M!B47),0) | F13: =IFERROR(F10/(Projections_24M!C47),0) | G13: =AVERAGE(E13:F13) | H13: Historical linked to P&L; plan linked to projections

Sheet Borrowing_Base
A1: Existing Borrowing Base Report
A2: Asset-based lending availability calculation (USD $000)
A4: Component | B4: Value | C4: Rate | D4: Advance Amount | E4: Notes / Source
A6: Accounts Receivable Base
A7: Gross A/R (from aging) | B7: =AR_Aging!K20 | E7: AR aging total
A8: Less: 90+ day balances | B8: =AR_Aging!J20 | E8: Ineligible aging bucket
A9: Less: dilution / cross-age reserve | B9: 220 | E9: Underwriting reserve input
A10: Net Eligible A/R | B10: =B7-B8-B9
A11: A/R Advance Rate | C11: 0.85 | D11: =B10*C11 | E11: Advance policy
A13: Inventory Base
A14: Inventory at Cost (current) | B14: =Inventory_Turnover!D11 | E14: Inventory report total
A15: Less: ineligible inventory reserve | B15: =B14*C15 | C15: 0.1 | E15: Obsolescence / slow mover reserve
A16: Net Eligible Inventory | B16: =B14-B15
A17: Inventory Advance Rate | C17: 0.5 | D17: =B16*C17 | E17: Advance policy
A19: Availability Summary
A20: Gross Borrowing Base | D20: =D11+D17
A21: Less: reserves / availability block | B21: 350
A22: Net Borrowing Availability | D22: =D20-B21
A23: Less: Revolver Outstanding | B23: =Debt_Schedule!E7 | E23: Debt schedule tie
A24: Excess Availability | D24: =D22-B23 | E24: Positive indicates incremental headroom

Sheet Projections_24M
A1: Financial Projections (24 Months)
A2: Monthly forecast with assumptions (USD $000)
A4: Assumptions
A5: Driver | B5: Value | C5: Unit | D5: Description | K5: Source URL
A6: Linehaul Monthly Growth | B6: 0.008 | C6: % | D6: Applied MoM | K6: https://www.apexlogistics.example/internal/forecast-assumptions
A7: Warehousing Monthly Growth | B7: 0.006 | C7: % | D7: Applied MoM | K7: https://www.apexlogistics.example/internal/forecast-assumptions
A8: Customs Monthly Growth | B8: 0.007 | C8: % | D8: Applied MoM | K8: https://www.apexlogistics.example/internal/forecast-assumptions
A9: Blended Gross Margin | B9: 0.238 | C9: % | D9: Gross profit / revenue | K9: https://www.apexlogistics.example/internal/forecast-assumptions
A10: OpEx Ratio | B10: 0.145 | C10: % | D10: Operating expense ratio | K10: https://www.apexlogistics.example/internal/forecast-assumptions
A11: D&A Ratio | B11: 0.023 | C11: % | D11: Depreciation as % revenue | K11: https://www.apexlogistics.example/internal/forecast-assumptions
A12: Interest Ratio | B12: 0.012 | C12: % | D12: Interest as % revenue | K12: https://www.apexlogistics.example/internal/forecast-assumptions
A13: Tax Rate | B13: 0.27 | C13: % | D13: Effective tax rate | K13: https://www.apexlogistics.example/internal/forecast-assumptions
A14: Capex Ratio | B14: 0.026 | C14: % | D14: Capex as % revenue | K14: https://www.apexlogistics.example/internal/forecast-assumptions
A15: NWC Ratio | B15: 0.118 | C15: % | D15: Net working capital as % revenue | K15: https://www.apexlogistics.example/internal/forecast-assumptions
A17: Monthly Projection
A18: Month | B18: Linehaul Rev | C18: Warehousing Rev | D18: Customs Rev | E18: Total Revenue | F18: Gross Profit | G18: EBITDA | H18: Net Income | I18: Capex | J18: Ending Cash | K18: Source URL
A19: 46054 | B19: =ROUND('P&L'!E7*(1+$B$6),0) | C19: =ROUND('P&L'!E8*(1+$B$7),0) | D19: =ROUND('P&L'!E9*(1+$B$8),0) | E19: =SUM(B19:D19) | F19: =E19*$B$9 | G19: =F19-(E19*$B$10) | H19: =MAX((G19-E19*$B$11-E19*$B$12)*(1-$B$13),0) | I19: =E19*$B$14 | J19: =Cash_Flow!E29+H19-I19-(E19*$B$15-'P&L'!E10*$B$15) | K19: https://www.apexlogistics.example/internal/forecast-model
A20: 46082 | B20: =ROUND(B19*(1+$B$6),0) | C20: =ROUND(C19*(1+$B$7),0) | D20: =ROUND(D19*(1+$B$8),0) | E20: =SUM(B20:D20) | F20: =E20*$B$9 | G20: =F20-(E20*$B$10) | H20: =MAX((G20-E20*$B$11-E20*$B$12)*(1-$B$13),0) | I20: =E20*$B$14 | J20: =J19+H20-I20-(E20*$B$15-E19*$B$15) | K20: https://www.apexlogistics.example/internal/forecast-model
A21: 46113 | B21: =ROUND(B20*(1+$B$6),0) | C21: =ROUND(C20*(1+$B$7),0) | D21: =ROUND(D20*(1+$B$8),0) | E21: =SUM(B21:D21) | F21: =E21*$B$9 | G21: =F21-(E21*$B$10) | H21: =MAX((G21-E21*$B$11-E21*$B$12)*(1-$B$13),0) | I21: =E21*$B$14 | J21: =J20+H21-I21-(E21*$B$15-E20*$B$15) | K21: https://www.apexlogistics.example/internal/forecast-model
A22: 46143 | B22: =ROUND(B21*(1+$B$6),0) | C22: =ROUND(C21*(1+$B$7),0) | D22: =ROUND(D21*(1+$B$8),0) | E22: =SUM(B22:D22) | F22: =E22*$B$9 | G22: =F22-(E22*$B$10) | H22: =MAX((G22-E22*$B$11-E22*$B$12)*(1-$B$13),0) | I22: =E22*$B$14 | J22: =J21+H22-I22-(E22*$B$15-E21*$B$15) | K22: https://www.apexlogistics.example/internal/forecast-model
A23: 46174 | B23: =ROUND(B22*(1+$B$6),0) | C23: =ROUND(C22*(1+$B$7),0) | D23: =ROUND(D22*(1+$B$8),0) | E23: =SUM(B23:D23) | F23: =E23*$B$9 | G23: =F23-(E23*$B$10) | H23: =MAX((G23-E23*$B$11-E23*$B$12)*(1-$B$13),0) | I23: =E23*$B$14 | J23: =J22+H23-I23-(E23*$B$15-E22*$B$15) | K23: https://www.apexlogistics.example/internal/forecast-model
A24: 46204 | B24: =ROUND(B23*(1+$B$6),0) | C24: =ROUND(C23*(1+$B$7),0) | D24: =ROUND(D23*(1+$B$8),0) | E24: =SUM(B24:D24) | F24: =E24*$B$9 | G24: =F24-(E24*$B$10) | H24: =MAX((G24-E24*$B$11-E24*$B$12)*(1-$B$13),0) | I24: =E24*$B$14 | J24: =J23+H24-I24-(E24*$B$15-E23*$B$15) | K24: https://www.apexlogistics.example/internal/forecast-model
A25: 46235 | B25: =ROUND(B24*(1+$B$6),0) | C25: =ROUND(C24*(1+$B$7),0) | D25: =ROUND(D24*(1+$B$8),0) | E25: =SUM(B25:D25) | F25: =E25*$B$9 | G25: =F25-(E25*$B$10) | H25: =MAX((G25-E25*$B$11-E25*$B$12)*(1-$B$13),0) | I25: =E25*$B$14 | J25: =J24+H25-I25-(E25*$B$15-E24*$B$15) | K25: https://www.apexlogistics.example/internal/forecast-model
A26: 46266 | B26: =ROUND(B25*(1+$B$6),0) | C26: =ROUND(C25*(1+$B$7),0) | D26: =ROUND(D25*(1+$B$8),0) | E26: =SUM(B26:D26) | F26: =E26*$B$9 | G26: =F26-(E26*$B$10) | H26: =MAX((G26-E26*$B$11-E26*$B$12)*(1-$B$13),0) | I26: =E26*$B$14 | J26: =J25+H26-I26-(E26*$B$15-E25*$B$15) | K26: https://www.apexlogistics.example/internal/forecast-model
A27: 46296 | B27: =ROUND(B26*(1+$B$6),0) | C27: =ROUND(C26*(1+$B$7),0) | D27: =ROUND(D26*(1+$B$8),0) | E27: =SUM(B27:D27) | F27: =E27*$B$9 | G27: =F27-(E27*$B$10) | H27: =MAX((G27-E27*$B$11-E27*$B$12)*(1-$B$13),0) | I27: =E27*$B$14 | J27: =J26+H27-I27-(E27*$B$15-E26*$B$15) | K27: https://www.apexlogistics.example/internal/forecast-model
A28: 46327 | B28: =ROUND(B27*(1+$B$6),0) | C28: =ROUND(C27*(1+$B$7),0) | D28: =ROUND(D27*(1+$B$8),0) | E28: =SUM(B28:D28) | F28: =E28*$B$9 | G28: =F28-(E28*$B$10) | H28: =MAX((G28-E28*$B$11-E28*$B$12)*(1-$B$13),0) | I28: =E28*$B$14 | J28: =J27+H28-I28-(E28*$B$15-E27*$B$15) | K28: https://www.apexlogistics.example/internal/forecast-model
A29: 46357 | B29: =ROUND(B28*(1+$B$6),0) | C29: =ROUND(C28*(1+$B$7),0) | D29: =ROUND(D28*(1+$B$8),0) | E29: =SUM(B29:D29) | F29: =E29*$B$9 | G29: =F29-(E29*$B$10) | H29: =MAX((G29-E29*$B$11-E29*$B$12)*(1-$B$13),0) | I29: =E29*$B$14 | J29: =J28+H29-I29-(E29*$B$15-E28*$B$15) | K29: https://www.apexlogistics.example/internal/forecast-model
A30: 46388 | B30: =ROUND(B29*(1+$B$6),0) | C30: =ROUND(C29*(1+$B$7),0) | D30: =ROUND(D29*(1+$B$8),0) | E30: =SUM(B30:D30) | F30: =E30*$B$9 | G30: =F30-(E30*$B$10) | H30: =MAX((G30-E30*$B$11-E30*$B$12)*(1-$B$13),0) | I30: =E30*$B$14 | J30: =J29+H30-I30-(E30*$B$15-E29*$B$15) | K30: https://www.apexlogistics.example/internal/forecast-model
A31: 46419 | B31: =ROUND(B30*(1+$B$6),0) | C31: =ROUND(C30*(1+$B$7),0) | D31: =ROUND(D30*(1+$B$8),0) | E31: =SUM(B31:D31) | F31: =E31*$B$9 | G31: =F31-(E31*$B$10) | H31: =MAX((G31-E31*$B$11-E31*$B$12)*(1-$B$13),0) | I31: =E31*$B$14 | J31: =J30+H31-I31-(E31*$B$15-E30*$B$15) | K31: https://www.apexlogistics.example/internal/forecast-model
... A42: 46753 | B42: =ROUND(B41*(1+$B$6),0) | C42: =ROUND(C41*(1+$B$7),0) | D42: =ROUND(D41*(1+$B$8),0) | E42: =SUM(B42:D42) | F42: =E42*$B$9 | G42: =F42-(E42*$B$10) | H42: =MAX((G42-E42*$B$11-E42*$B$12)*(1-$B$13),0) | I42: =E42*$B$14 | J42: =J41+H42-I42-(E42*$B$15-E41*$B$15) | K42: https://www.apexlogistics.example/internal/forecast-model
A45: Annual Summary
A46: Metric | B46: 2026E | C46: 2027E
A47: Total Revenue | B47: =SUMIFS(E19:E42,A19:A42,">="&DATE(2026,1,1),A19:A42,"<="&DATE(2026,12,31)) | C47: =SUMIFS(E19:E42,A19:A42,">="&DATE(2027,1,1),A19:A42,"<="&DATE(2027,12,31))
A48: EBITDA | B48: =SUMIFS(G19:G42,A19:A42,">="&DATE(2026,1,1),A19:A42,"<="&DATE(2026,12,31)) | C48: =SUMIFS(G19:G42,A19:A42,">="&DATE(2027,1,1),A19:A42,"<="&DATE(2027,12,31))
A49: Net Income | B49: =SUMIFS(H19:H42,A19:A42,">="&DATE(2026,1,1),A19:A42,"<="&DATE(2026,12,31)) | C49: =SUMIFS(H19:H42,A19:A42,">="&DATE(2027,1,1),A19:A42,"<="&DATE(2027,12,31))
A50: Ending Cash | B50: =INDEX(J19:J42,MATCH(DATE(2026,12,1),A19:A42,0)) | C50: =INDEX(J19:J42,MATCH(DATE(2027,12,1),A19:A42,0))
